Workbook

Sheet Sheet1
A1: No. | B1: ID Equipo | C1: Ubicación | D1: COLOR | E1: NOMBRE DE DISPOSITIVO | F1: PLANTA | G1: COMENTARIOS | H1: CODIGO DE COLORES
A2: 1 | B2: 6C8CWX3 | C2: AREA AUTOCLAVE (S/V AUTOCLAVE) | D2: GRIS | E2: COMPUTADORA DE ESCRITORIO | F2: B1 | H2: VERDE | I2: EQUIPOS CON SISTEMA SRK DE LINEAS
A3: 2 | B3: 5B2405T42731 | C3: AREA AUTOCLAVE (S/V AUTOCLAVE) | D3: GRIS | E3: =_xlfn.XLOOKUP(Table1[[#This Row],[ID Equipo]],Hoja2!A:A,Hoja2!D:D,"NO SE ENCONTRO",0) -> UPS | F3: B1 | H3: GRIS | I3: TODOS LOS EQUIPOS QUE NO TIENEN SISTEMA SRK
A4: 3 | B4: 6ZJXDF3 | C4: AREA CORTE 1 (S/V EXT.S) | D4: GRIS | E4: =_xlfn.XLOOKUP(Table1[[#This Row],[ID Equipo]],Hoja2!A:A,Hoja2!D:D,"NO SE ENCONTRO",0) -> COMPUTADORA DE ESCRITORIO | F4: B1 | H4: AZUL | I4: TODOS LOS EQUIPOS QUE NO ESTAN EN AREA DE PRODUCCION
A5: 4 | B5: 4B1131P19277 | C5: AREA CORTE 1 (S/V EXT.S) | D5: GRIS | E5: =_xlfn.XLOOKUP(Table1[[#This Row],[ID Equipo]],Hoja2!A:A,Hoja2!D:D,"NO SE ENCONTRO",0) -> UPS | F5: B1 | H5: ROJO | I5: CORRECTIVOS
A6: 5 | B6: 6FCCWX3 | C6: AREA DE ACCORD (S/V LINEAS) | D6: GRIS | E6: =_xlfn.XLOOKUP(Table1[[#This Row],[ID Equipo]],Hoja2!A:A,Hoja2!D:D,"NO SE ENCONTRO",0) -> COMPUTADORA DE ESCRITORIO | F6: B1 | H6: AMARILLO | I6: TODOS LOS EQUIPOS QUE ESTAN EN INDIVIDUAL
A7: 6 | B7: 4B1128P48603 | C7: AREA DE ACCORD (S/V LINEAS) | D7: GRIS | E7: =_xlfn.XLOOKUP(Table1[[#This Row],[ID Equipo]],Hoja2!A:A,Hoja2!D:D,"NO SE ENCONTRO",0) -> UPS | F7: B1 | H7: ROSA | I7: SOPORTE SITE 1 Y 2 STOCK
A8: 7 | B8: 6DJQ482 | C8: AREA DE LOCKERS (ASISTENTE DE MA) | D8: AZUL | E8: =_xlfn.XLOOKUP(Table1[[#This Row],[ID Equipo]],Hoja2!A:A,Hoja2!D:D,"NO SE ENCONTRO",0) -> COMPUTADORA DE ESCRITORIO | F8: B1
A9: 8 | B9: 4B1519P47249 | C9: AREA DE LOCKERS (ASISTENTE DE MA) | D9: AZUL | E9: =_xlfn.XLOOKUP(Table1[[#This Row],[ID Equipo]],Hoja2!A:A,Hoja2!D:D,"NO SE ENCONTRO",0) -> UPS | F9: B1 | H9: NOMENCLATURA DE UBICACIONES SITE 1
A10: 9 | B10: CFCCWX3 | C10: AREA DE LOCKERS (S/V HORNOS IZQ) | D10: AZUL | E10: =_xlfn.XLOOKUP(Table1[[#This Row],[ID Equipo]],Hoja2!A:A,Hoja2!D:D,"NO SE ENCONTRO",0) -> COMPUTADORA DE ESCRITORIO | F10: B1 | H10: ANAQUELES: A,T,C,D
A11: 10 | B11: 4B1015P28602 | C11: AREA DE LOCKERS (S/V HORNOS IZQ) | D11: AZUL | E11: =_xlfn.XLOOKUP(Table1[[#This Row],[ID Equipo]],Hoja2!A:A,Hoja2!D:D,"NO SE ENCONTRO",0) -> UPS | F11: B1 | H11: NIVELES: 1 al 6
A12: 11 | B12: CC8CWX3 | C12: AREA DE LOCKERS (S/V LINEAS) | D12: AZUL | E12: COMPUTADORA DE ESCRITORIO | F12: B1
A13: 12 | B13: 3B1044X10037 | C13: AREA DE LOCKERS (S/V LINEAS) | D13: AZUL | E13: =_xlfn.XLOOKUP(Table1[[#This Row],[ID Equipo]],Hoja2!A:A,Hoja2!D:D,"NO SE ENCONTRO",0) -> UPS | F13: B1
A14: 13 | B14: 8QHW0Q2 | C14: AREA INSPECCION DE INCOMING (LIDER) | D14: AZUL | E14: =_xlfn.XLOOKUP(Table1[[#This Row],[ID Equipo]],Hoja2!A:A,Hoja2!D:D,"NO SE ENCONTRO",0) -> COMPUTADORA DE ESCRITORIO | F14: B1
A15: 14 | B15: 4B1226P31318 | C15: AREA INSPECCION DE INCOMING (LIDER) | D15: AZUL | E15: =_xlfn.XLOOKUP(Table1[[#This Row],[ID Equipo]],Hoja2!A:A,Hoja2!D:D,"NO SE ENCONTRO",0) -> UPS | F15: B1
A16: 15 | B16: 8LF2FF3 | C16: AUDITORIA DE PROCESOS | D16: AZUL | E16: =_xlfn.XLOOKUP(Table1[[#This Row],[ID Equipo]],Hoja2!A:A,Hoja2!D:D,"NO SE ENCONTRO",0) -> COMPUTADORA DE ESCRITORIO | F16: B1
A17: 16 | B17: 0B2317N03326 | C17: AUDITORIA DE PROCESOS | D17: AZUL | E17: =_xlfn.XLOOKUP(Table1[[#This Row],[ID Equipo]],Hoja2!A:A,Hoja2!D:D,"NO SE ENCONTRO",0) -> UPS | F17: B1
A18: 17 | B18: 0B2319N02794 | C18: AUTOCLAVE (PANEL DE CONTROL AUT.2) | D18: AMARILLO | E18: =_xlfn.XLOOKUP(Table1[[#This Row],[ID Equipo]],Hoja2!A:A,Hoja2!D:D,"NO SE ENCONTRO",0) -> UPS | F18: B1
A19: 18 | B19: FRP3RP2 | C19: AUTOCLAVE 1 (SISTEMA SRK) | D19: VERDE | E19: =_xlfn.XLOOKUP(Table1[[#This Row],[ID Equipo]],Hoja2!A:A,Hoja2!D:D,"NO SE ENCONTRO",0) -> COMPUTADORA DE ESCRITORIO | F19: B1
A20: 19 | B20: 29J120702698 | C20: AUTOCLAVE 1 (SISTEMA SRK) | D20: VERDE | E20: =_xlfn.XLOOKUP(Table1[[#This Row],[ID Equipo]],Hoja2!A:A,Hoja2!D:D,"NO SE ENCONTRO",0) -> IMPRESORA TERMICA | F20: B1
A21: 20 | B21: 0B2425L07173 | C21: AUTOCLAVE 1 (SISTEMA SRK) | D21: VERDE | E21: =_xlfn.XLOOKUP(Table1[[#This Row],[ID Equipo]],Hoja2!A:A,Hoja2!D:D,"NO SE ENCONTRO",0) -> UPS | F21: B1
A22: 21 | B22: J7T8922 | C22: AUTOCLAVE 3 (SISTEMA SRK) | D22: VERDE | E22: =_xlfn.XLOOKUP(Table1[[#This Row],[ID Equipo]],Hoja2!A:A,Hoja2!D:D,"NO SE ENCONTRO",0) -> COMPUTADORA DE ESCRITORIO | F22: B1
A23: 22 | B23: 29J161900202 | C23: AUTOCLAVE 3 (SISTEMA SRK) | D23: VERDE | E23: =_xlfn.XLOOKUP(Table1[[#This Row],[ID Equipo]],Hoja2!A:A,Hoja2!D:D,"NO SE ENCONTRO",0) -> IMPRESORA TERMICA | F23: B1
A24: 23 | B24: 4B1508P03448 | C24: AUTOCLAVE 3 (SISTEMA SRK) | D24: VERDE | E24: =_xlfn.XLOOKUP(Table1[[#This Row],[ID Equipo]],Hoja2!A:A,Hoja2!D:D,"NO SE ENCONTRO",0) -> UPS | F24: B1
... A30: 29 | B30: 4B1124P31676 | C30: AUTOCLAVE 5 (SISTEMA SRK) | D30: VERDE | E30: =_xlfn.XLOOKUP(Table1[[#This Row],[ID Equipo]],Hoja2!A:A,Hoja2!D:D,"NO SE ENCONTRO",0) -> UPS | F30: B1
A31: 30 | B31: 4CFZSD2 | C31: AUTOCLAVE 6 (SISTEMA SRK) | D31: VERDE | E31: COMPUTADORA DE ESCRITORIO | F31: B1
A32: 31 | B32: 29J180501422 | C32: AUTOCLAVE 6 (SISTEMA SRK) | D32: VERDE | E32: =_xlfn.XLOOKUP(Table1[[#This Row],[ID Equipo]],Hoja2!A:A,Hoja2!D:D,"NO SE ENCONTRO",0) -> IMPRESORA TERMICA | F32: B1
A33: 32 | B33: 0B2449L46499 | C33: AUTOCLAVE 6 (SISTEMA SRK) | D33: VERDE | E33: UPS | F33: B1
A34: 33 | B34: 8JDFTW1 | C34: BORDES (SISTEMA SRK) | D34: VERDE | E34: =_xlfn.XLOOKUP(Table1[[#This Row],[ID Equipo]],Hoja2!A:A,Hoja2!D:D,"NO SE ENCONTRO",0) -> COMPUTADORA DE ESCRITORIO | F34: B1
A35: 34 | B35: D6N233550270 | C35: BORDES (SISTEMA SRK) | D35: VERDE | E35: =_xlfn.XLOOKUP(Table1[[#This Row],[ID Equipo]],Hoja2!A:A,Hoja2!D:D,"NO SE ENCONTRO",0) -> IMPRESORA TERMICA | F35: B1
A36: 35 | B36: 4B1146P49243 | C36: BORDES (SISTEMA SRK) | D36: VERDE | E36: =_xlfn.XLOOKUP(Table1[[#This Row],[ID Equipo]],Hoja2!A:A,Hoja2!D:D,"NO SE ENCONTRO",0) -> UPS | F36: B1
A37: 36 | B37: 4B1613P63260 | C37: CAMARA DE VIGILANCIA MEZZANINE APQP | D37: AMARILLO | E37: =_xlfn.XLOOKUP(Table1[[#This Row],[ID Equipo]],Hoja2!A:A,Hoja2!D:D,"NO SE ENCONTRO",0) -> UPS | F37: B1
A38: 37 | B38: HFXR5V1 | C38: CAMARAS 1 (SISTEMA SRK) | D38: VERDE | E38: =_xlfn.XLOOKUP(Table1[[#This Row],[ID Equipo]],Hoja2!A:A,Hoja2!D:D,"NO SE ENCONTRO",0) -> COMPUTADORA DE ESCRITORIO | F38: B1
A39: 38 | B39: 29J152401805 | C39: CAMARAS 1 (SISTEMA SRK) | D39: VERDE | E39: =_xlfn.XLOOKUP(Table1[[#This Row],[ID Equipo]],Hoja2!A:A,Hoja2!D:D,"NO SE ENCONTRO",0) -> IMPRESORA TERMICA | F39: B1
A40: 39 | B40: 4B1146P47173 | C40: CAMARAS 1 (SISTEMA SRK) | D40: VERDE | E40: =_xlfn.XLOOKUP(Table1[[#This Row],[ID Equipo]],Hoja2!A:A,Hoja2!D:D,"NO SE ENCONTRO",0) -> UPS | F40: B1
A41: 40 | B41: HFNW5V1 | C41: CAMPANA Y PLASMA (SISTEMA SRK) | D41: VERDE | E41: =_xlfn.XLOOKUP(Table1[[#This Row],[ID Equipo]],Hoja2!A:A,Hoja2!D:D,"NO SE ENCONTRO",0) -> COMPUTADORA DE ESCRITORIO | F41: B1
A42: 41 | B42: D6N224051186 | C42: CAMPANA Y PLASMA (SISTEMA SRK) | D42: VERDE | E42: =_xlfn.XLOOKUP(Table1[[#This Row],[ID Equipo]],Hoja2!A:A,Hoja2!D:D,"NO SE ENCONTRO",0) -> IMPRESORA TERMICA | F42: B1
A43: 42 | B43: 4B1508P05815 | C43: CAMPANA Y PLASMA (SISTEMA SRK) | D43: VERDE | E43: =_xlfn.XLOOKUP(Table1[[#This Row],[ID Equipo]],Hoja2!A:A,Hoja2!D:D,"NO SE ENCONTRO",0) -> UPS | F43: B1
A44: 43 | B44: 0B2449L30129 | C44: CCTV PARED ARRIBA FRENTE A LAS 300'S | D44: AMARILLO | E44: UPS | F44: B1
A45: 44 | B45: FLF7BZ2 | C45: COMUNICACION (JENIFFER CHAVEZ) | D45: AZUL | E45: COMPUTADORA DE ESCRITORIO | F45: B1
...

Sheet Hoja1
A1: 0B2137N07360 | B1: AUDITORIA 200% (SITEMA SRK) | C1: AZUL | D1: UPS
A2: DQK1LN1 | B2: AUDITORIA 200% (SITEMA SRK) | C2: AZUL | D2: COMPUTADORA DE ESCRITORIO
A3: 4B1508P05779 | B3: EHS (CAPTURISTA DE SCRAP) | C3: AZUL | D3: UPS
A4: 6DJ0582 | B4: EHS (CAPTURISTA DE SCRAP) | C4: AZUL | D4: COMPUTADORA DE ESCRITORIO
A5: CVQ0Z12 | B5: HORNO 01 (SISTEMA SRK) | C5: VERDE | D5: COMPUTADORA DE ESCRITORIO
A6: 29J152401795 | B6: HORNO 01 (SISTEMA SRK) | C6: VERDE | D6: IMPRESORA TERMICA
A7: 4B1543P33154 | B7: HORNO 01 (SISTEMA SRK) | C7: VERDE | D7: UPS
A8: HFWW5V1 | B8: HORNO 03 (SISTEMA SRK) | C8: VERDE | D8: COMPUTADORA DE ESCRITORIO
A9: 29J120702723 | B9: HORNO 03 (SISTEMA SRK) | C9: VERDE | D9: IMPRESORA TERMICA
A10: 4B1329P43899 | B10: HORNO 03 (SISTEMA SRK) | C10: VERDE | D10: UPS
A11: HFTT5V1 | B11: HORNO 04 (SISTEMA SRK) | C11: VERDE | D11: COMPUTADORA DE ESCRITORIO
A12: 29J120702721 | B12: HORNO 04 (SISTEMA SRK) | C12: VERDE | D12: IMPRESORA TERMICA
... A194: 4B1205P42855 | B194: VIJILANCIA (REPISA) | C194: AZUL | D194: UPS

Sheet Laptops
A1: 608 | B1: FS3NVL3 | C1: PE (VICTOR ALEJANDRO ORTIZ VALTIERRA) | D1: AMARILLO | E1: LAPTOP | F1: PLANTA MIXING
A2: 609 | B2: 3CHSPF2 | C2: PE (VICTOR ALEJANDRO ORTIZ VALTIERRA) | D2: AMARILLO | E2: LAPTOP | F2: PLANTA MIXING
A3: 610 | B3: 5S80562 | C3: AD (ENFERMERAS) | D3: AMARILLO | E3: LAPTOP | F3: PLANTA SATELITE
A4: 611 | B4: FKKH314TR | C4: MA (OSCAR URIEL PEREZ HERNANDEZ) | D4: AMARILLO | E4: LAPTOP | F4: PLANTA SATELITE
A5: 612 | B5: 88N5Z93 | C5: MA (ROBERTO RUIZ TERRAZAS) | D5: AMARILLO | E5: LAPTOP | F5: PLANTA SATELITE
A6: 613 | B6: 1X2KL32 | C6: PC (DAVID ELOY SALAS GONZALEZ) | D6: AMARILLO | E6: LAPTOP | F6: PLANTA SATELITE
A7: 614 | B7: G2PSPF2 | C7: QA (SANDRA OLIVIA HERNANDEZ DIAZ) | D7: AMARILLO | E7: LAPTOP | F7: PLANTA SATELITE
A8: 615 | B8: 6Q1LLY3 | C8: QA (SOCORRO MADAVI ARZATE HERNANDEZ) | D8: AMARILLO | E8: LAPTOP | F8: PLANTA SATELITE
A9: 616 | B9: 9HNRWW1 | C9: TR (INDUCCION) | D9: AMARILLO | E9: LAPTOP | F9: PLANTA SATELITE
A10: 617 | B10: 54S4WF2 | C10: PC (FRANCISCO JAVIER RODRIGUEZ LEON | D10: AMARILLO | E10: LAPTOP | F10: BODEGA

Sheet Hoja2
A1: 5B2405T42731 | B1: AREA AUTOCLAVE (S/V AUTOCLAVE) | C1: GRIS | D1: =_xlfn.IFNA(VLOOKUP(A1,'[1]Validacion CPUs'!C:H,6,FALSE),_xlfn.IFNA(VLOOKUP(A1,'[1]Validacion TP'!A:H,8,FALSE),VLOOKUP(A1,'[1]Validacion UPS'!A:H,8,FALSE))) -> UPS
A2: CFCCWX3 | B2: AREA AUTOCLAVE (S/V AUTOCLAVE) | C2: GRIS | D2: =_xlfn.IFNA(VLOOKUP(A2,'[1]Validacion CPUs'!C:H,6,FALSE),_xlfn.IFNA(VLOOKUP(A2,'[1]Validacion TP'!A:H,8,FALSE),VLOOKUP(A2,'[1]Validacion UPS'!A:H,8,FALSE))) -> COMPUTADORA DE ESCRITORIO
A3: 6ZJXDF3 | B3: AREA CORTE 1 (S/V EXT.S) | C3: GRIS | D3: =_xlfn.IFNA(VLOOKUP(A3,'[1]Validacion CPUs'!C:H,6,FALSE),_xlfn.IFNA(VLOOKUP(A3,'[1]Validacion TP'!A:H,8,FALSE),VLOOKUP(A3,'[1]Validacion UPS'!A:H,8,FALSE))) -> COMPUTADORA DE ESCRITORIO
A4: 4B1131P19277 | B4: AREA CORTE 1 (S/V EXT.S) | C4: GRIS | D4: =_xlfn.IFNA(VLOOKUP(A4,'[1]Validacion CPUs'!C:H,6,FALSE),_xlfn.IFNA(VLOOKUP(A4,'[1]Validacion TP'!A:H,8,FALSE),VLOOKUP(A4,'[1]Validacion UPS'!A:H,8,FALSE))) -> UPS
A5: 4B1128P48603 | B5: AREA DE ACCORD (S/V LINEAS) | C5: GRIS | D5: =_xlfn.IFNA(VLOOKUP(A5,'[1]Validacion CPUs'!C:H,6,FALSE),_xlfn.IFNA(VLOOKUP(A5,'[1]Validacion TP'!A:H,8,FALSE),VLOOKUP(A5,'[1]Validacion UPS'!A:H,8,FALSE))) -> UPS
A6: 8LFVDF3 | B6: AREA DE ACCORD (S/V LINEAS) | C6: GRIS | D6: =_xlfn.IFNA(VLOOKUP(A6,'[1]Validacion CPUs'!C:H,6,FALSE),_xlfn.IFNA(VLOOKUP(A6,'[1]Validacion TP'!A:H,8,FALSE),VLOOKUP(A6,'[1]Validacion UPS'!A:H,8,FALSE))) -> COMPUTADORA DE ESCRITORIO
A7: 4B1519P47249 | B7: AREA DE LOCKERS (ASISTENTE DE MA) | C7: AZUL | D7: =_xlfn.IFNA(VLOOKUP(A7,'[1]Validacion CPUs'!C:H,6,FALSE),_xlfn.IFNA(VLOOKUP(A7,'[1]Validacion TP'!A:H,8,FALSE),VLOOKUP(A7,'[1]Validacion UPS'!A:H,8,FALSE))) -> UPS
A8: 6DJQ482 | B8: AREA DE LOCKERS (ASISTENTE DE MA) | C8: AZUL | D8: =_xlfn.IFNA(VLOOKUP(A8,'[1]Validacion CPUs'!C:H,6,FALSE),_xlfn.IFNA(VLOOKUP(A8,'[1]Validacion TP'!A:H,8,FALSE),VLOOKUP(A8,'[1]Validacion UPS'!A:H,8,FALSE))) -> COMPUTADORA DE ESCRITORIO
A9: 49CRM83 | B9: AREA DE LOCKERS (S/V HORNOS IZQ) | C9: AZUL | D9: =_xlfn.IFNA(VLOOKUP(A9,'[1]Validacion CPUs'!C:H,6,FALSE),_xlfn.IFNA(VLOOKUP(A9,'[1]Validacion TP'!A:H,8,FALSE),VLOOKUP(A9,'[1]Validacion UPS'!A:H,8,FALSE))) -> COMPUTADORA DE ESCRITORIO
A10: 4B1015P28602 | B10: AREA DE LOCKERS (S/V HORNOS IZQ) | C10: AZUL | D10: =_xlfn.IFNA(VLOOKUP(A10,'[1]Validacion CPUs'!C:H,6,FALSE),_xlfn.IFNA(VLOOKUP(A10,'[1]Validacion TP'!A:H,8,FALSE),VLOOKUP(A10,'[1]Validacion UPS'!A:H,8,FALSE))) -> UPS
A11: 3B1044X10037 | B11: AREA DE LOCKERS (S/V LINEAS) | C11: AZUL | D11: =_xlfn.IFNA(VLOOKUP(A11,'[1]Validacion CPUs'!C:H,6,FALSE),_xlfn.IFNA(VLOOKUP(A11,'[1]Validacion TP'!A:H,8,FALSE),VLOOKUP(A11,'[1]Validacion UPS'!A:H,8,FALSE))) -> UPS
A12: 6ZJTDF3 | B12: AREA DE LOCKERS (S/V LINEAS) | C12: AZUL | D12: =_xlfn.IFNA(VLOOKUP(A12,'[1]Validacion CPUs'!C:H,6,FALSE),_xlfn.IFNA(VLOOKUP(A12,'[1]Validacion TP'!A:H,8,FALSE),VLOOKUP(A12,'[1]Validacion UPS'!A:H,8,FALSE))) -> COMPUTADORA DE ESCRITORIO
... A375: 9Y4PQD2 | B375: TOOLCRIB (VENTANILLA) | C375: AZUL | D375: =_xlfn.IFNA(VLOOKUP(A375,'[1]Validacion CPUs'!C:H,6,FALSE),_xlfn.IFNA(VLOOKUP(A375,'[1]Validacion TP'!A:H,8,FALSE),VLOOKUP(A375,'[1]Validacion UPS'!A:H,8,FALSE))) -> COMPUTADORA DE ESCRITORIO
A376: 4B1738P34064 | B376: LOCALIZAR | D376: =_xlfn.IFNA(VLOOKUP(A376,'[1]Validacion CPUs'!C:H,6,FALSE),_xlfn.IFNA(VLOOKUP(A376,'[1]Validacion TP'!A:H,8,FALSE),VLOOKUP(A376,'[1]Validacion UPS'!A:H,8,FALSE))) -> UPS
A377: 4B1821P03680 | B377: LOCALIZAR | D377: =_xlfn.IFNA(VLOOKUP(A377,'[1]Validacion CPUs'!C:H,6,FALSE),_xlfn.IFNA(VLOOKUP(A377,'[1]Validacion TP'!A:H,8,FALSE),VLOOKUP(A377,'[1]Validacion UPS'!A:H,8,FALSE))) -> UPS
A378: 4B1836P13698 | B378: LOCALIZAR | D378: =_xlfn.IFNA(VLOOKUP(A378,'[1]Validacion CPUs'!C:H,6,FALSE),_xlfn.IFNA(VLOOKUP(A378,'[1]Validacion TP'!A:H,8,FALSE),VLOOKUP(A378,'[1]Validacion UPS'!A:H,8,FALSE))) -> UPS
A379: 9B1835A19461 | B379: LOCALIZAR | D379: =_xlfn.IFNA(VLOOKUP(A379,'[1]Validacion CPUs'!C:H,6,FALSE),_xlfn.IFNA(VLOOKUP(A379,'[1]Validacion TP'!A:H,8,FALSE),VLOOKUP(A379,'[1]Validacion UPS'!A:H,8,FALSE))) -> UPS
A380: 9B1835A19462 | B380: LOCALIZAR | D380: =_xlfn.IFNA(VLOOKUP(A380,'[1]Validacion CPUs'!C:H,6,FALSE),_xlfn.IFNA(VLOOKUP(A380,'[1]Validacion TP'!A:H,8,FALSE),VLOOKUP(A380,'[1]Validacion UPS'!A:H,8,FALSE))) -> UPS
A381: 9B1831A02357 | B381: LOCALIZAR | D381: =_xlfn.IFNA(VLOOKUP(A381,'[1]Validacion CPUs'!C:H,6,FALSE),_xlfn.IFNA(VLOOKUP(A381,'[1]Validacion TP'!A:H,8,FALSE),VLOOKUP(A381,'[1]Validacion UPS'!A:H,8,FALSE))) -> UPS
A382: 9B1832A02956 | B382: LOCALIZAR | D382: =_xlfn.IFNA(VLOOKUP(A382,'[1]Validacion CPUs'!C:H,6,FALSE),_xlfn.IFNA(VLOOKUP(A382,'[1]Validacion TP'!A:H,8,FALSE),VLOOKUP(A382,'[1]Validacion UPS'!A:H,8,FALSE))) -> UPS
A383: 9B1831A02314 | B383: LOCALIZAR | D383: =_xlfn.IFNA(VLOOKUP(A383,'[1]Validacion CPUs'!C:H,6,FALSE),_xlfn.IFNA(VLOOKUP(A383,'[1]Validacion TP'!A:H,8,FALSE),VLOOKUP(A383,'[1]Validacion UPS'!A:H,8,FALSE))) -> UPS
A384: 9B1836A28332 | B384: LOCALIZAR | D384: =_xlfn.IFNA(VLOOKUP(A384,'[1]Validacion CPUs'!C:H,6,FALSE),_xlfn.IFNA(VLOOKUP(A384,'[1]Validacion TP'!A:H,8,FALSE),VLOOKUP(A384,'[1]Validacion UPS'!A:H,8,FALSE))) -> UPS
A385: 9B1832A03224 | B385: LOCALIZAR | D385: =_xlfn.IFNA(VLOOKUP(A385,'[1]Validacion CPUs'!C:H,6,FALSE),_xlfn.IFNA(VLOOKUP(A385,'[1]Validacion TP'!A:H,8,FALSE),VLOOKUP(A385,'[1]Validacion UPS'!A:H,8,FALSE))) -> UPS
A386: 4B1843P02137 | B386: LOCALIZAR | D386: =_xlfn.IFNA(VLOOKUP(A386,'[1]Validacion CPUs'!C:H,6,FALSE),_xlfn.IFNA(VLOOKUP(A386,'[1]Validacion TP'!A:H,8,FALSE),VLOOKUP(A386,'[1]Validacion UPS'!A:H,8,FALSE))) -> UPS
A387: 4B1843P02338 | B387: LOCALIZAR | D387: =_xlfn.IFNA(VLOOKUP(A387,'[1]Validacion CPUs'!C:H,6,FALSE),_xlfn.IFNA(VLOOKUP(A387,'[1]Validacion TP'!A:H,8,FALSE),VLOOKUP(A387,'[1]Validacion UPS'!A:H,8,FALSE))) -> UPS
... A413: 4B1131P36878 | B413: LOCALIZAR | D413: =_xlfn.IFNA(VLOOKUP(A413,'[1]Validacion CPUs'!C:H,6,FALSE),_xlfn.IFNA(VLOOKUP(A413,'[1]Validacion TP'!A:H,8,FALSE),VLOOKUP(A413,'[1]Validacion UPS'!A:H,8,FALSE))) -> UPS

Sheet BAJAS
A1: NO | B1: ID EQUIPO | C1: TIPO DE DISPOSITIVO | D1: MARCA | E1: MODELO | F1: ACTIVO FIJO | G1: UBICACION | H1: ESTADO (FUNCIONAL, NO FUNCIONAL) | I1: FOLIO BAJA | J1: FECHA BAJA | K1: MOTIVO BAJA | L1: FOLIO CORRECTIVO | M1: CALENDARIZAR (SI, NO)
A2: 1 | B2: CN02D81 | C2: COMPUTADORA DE ESCRITORIO | D2: DELL | E2: OPTIPLEX 170L | F2: DTR-1051555 | G2: SITE 2 | H2: NO FUNCIONAL | I2: EB31 | J2: 45819 | K2: EQUIPO OBSOLETO, NO CUMPLE CON LOS REQUERIMIENTOS PARA SU ACTUALIZACION | L2: NA | M2: NO
A3: 2 | B3: 5DX2SL1 | C3: COMPUTADORA DE ESCRITORIO | D3: DELL | E3: VOSTRO 230 | F3: DTR-1204807 | G3: SITE 1 | H3: FUNCIONAL | I3: EB112 | J3: 45996 | K3: NO SE ACTUALIZA A W11, FALTA DE SEGURIDAD EN EL SW | L3: NA | M3: NO
A4: 3 | B4: CZDJDP1 | C4: COMPUTADORA DE ESCRITORIO | D4: DELL | E4: VOSTRO 230 | F4: NA | G4: SITE 1 | H4: NO FUNCIONAL | I4: EB114 | J4: 45994 | K4: EQUIPO DAÑADO YA NO ENCIENDIO, DAÑO MOBO | L4: C1964 | M4: NO
A5: 4 | B5: 6VN1XQ1 | C5: COMPUTADORA DE ESCRITORIO | D5: DELL | E5: VOSTRO 230 | F5: DTR-1281601 | G5: SITE 1 | H5: FUNCIONAL | I5: EB111 | J5: 45996 | K5: NO SE ACTUALIZA A W11, FALTA DE SEGURIDAD EN EL SW | L5: NA | M5: NO
A6: 5 | B6: 5DY4SL1 | C6: COMPUTADORA DE ESCRITORIO | D6: DELL | E6: VOSTRO 230 | F6: DTR-1204803 | G6: SITE 1 | H6: FUNCIONAL | I6: EB84 | J6: 45974 | K6: NO SE ACTUALIZA A W11, FALTA DE SEGURIDAD EN EL SW | L6: NA | M6: NO
A7: 6 | B7: H9RJ9P1 | C7: COMPUTADORA DE ESCRITORIO | D7: DELL | E7: VOSTRO 230 | F7: NA | G7: SITE 1 | H7: FUNCIONAL | I7: EB85 | J7: 45974 | K7: NO SE ACTUALIZA A W11, FALTA DE SEGURIDAD EN EL SW | L7: NA | M7: NO
A8: 7 | B8: 347SGQ1 | C8: COMPUTADORA DE ESCRITORIO | D8: DELL | E8: VOSTRO 230 | F8: NA | G8: SITE 1 | H8: FUNCIONAL | I8: EB86 | J8: 45974 | K8: NO SE ACTUALIZA A W11, FALTA DE SEGURIDAD EN EL SW | L8: NA | M8: NO
A9: 8 | B9: BMLWJM1 | C9: COMPUTADORA DE ESCRITORIO | D9: DELL | E9: PRECISION T3500 | F9: NA | G9: SITE 2 | H9: NO FUNCIONAL | I9: EB90 | J9: 45980 | K9: EQUIPO OBSOLETO, NO CUMPLE CON LOS REQUERIMIENTOS PARA SU ACTUALIZACION | L9: NA | M9: NO
A10: 9 | B10: 5DY2SL1 | C10: COMPUTADORA DE ESCRITORIO | D10: DELL | E10: VOSTRO 230 | F10: DTR-1204805 | G10: SITE 1 | H10: FUNCIONAL | I10: EB165 | J10: 46051 | K10: NO SE ACTUALIZA A W11, FALTA DE SEGURIDAD EN EL SW | L10: NA | M10: NO
A11: 10 | B11: 5DX4SL1 | C11: COMPUTADORA DE ESCRITORIO | D11: DELL | E11: VOSTRO 230 | F11: DTR-1204806 | G11: SITE 1 | H11: FUNCIONAL | I11: EB164 | J11: 46051 | K11: NO SE ACTUALIZA A W11, FALTA DE SEGURIDAD EN EL SW | L11: NA | M11: NO
A12: 11 | B12: 347WGQ1 | C12: COMPUTADORA DE ESCRITORIO | D12: DELL | E12: VOSTRO 230 | F12: NA | G12: SITE 1 | H12: FUNCIONAL | I12: EB163 | J12: 46051 | K12: NO SE ACTUALIZA A W11, FALTA DE SEGURIDAD EN EL SW | L12: NA | M12: NO
A13: 12 | B13: 349QGQ1 | C13: COMPUTADORA DE ESCRITORIO | D13: DELL | E13: VOSTRO 230 | F13: NA | G13: SITE 1 | H13: FUNCIONAL | I13: EB162 | J13: 46051 | K13: NO SE ACTUALIZA A W11, FALTA DE SEGURIDAD EN EL SW | L13: NA | M13: NO
... A33: 32 | B33: 5DX7SL1 | C33: COMPUTADORA DE ESCRITORIO | D33: DELL | E33: VOSTRO 230 | F33: NA | G33: SITE 1 | H33: FUNCIONAL | I33: EB169 | J33: 46058 | K33: NO SE ACTUALIZA A W11, FALTA DE SEGURIDAD EN EL SW | L33: NA | M33: NO
